<sdf version='1.9'>
  <world name='iot_project_world'>
    <physics name='4ms' type='ignored'>
      <max_step_size>0.0040000000000000001</max_step_size>
      <real_time_factor>1</real_time_factor>
      <real_time_update_rate>1000</real_time_update_rate>
    </physics>
    <plugin name='ignition::gazebo::systems::Physics' filename='ignition-gazebo-physics-system'/>
    <plugin name='ignition::gazebo::systems::SceneBroadcaster' filename='ignition-gazebo-scene-broadcaster-system'/>
    <plugin name='ignition::gazebo::systems::UserCommands' filename='ignition-gazebo-user-commands-system'/>
    <plugin name='ignition::gazebo::systems::Sensors' filename='ignition-gazebo-sensors-system'>
      <render_engine>ogre2</render_engine>
    </plugin>
    <gravity>0 0 -9.8</gravity>
    <magnetic_field>6e-06 2.3e-05 -4.2e-05</magnetic_field>
    <atmosphere type='adiabatic'/>
    <scene>
      <ambient>0.4 0.4 0.4 1</ambient>
      <background>0.7 0.7 0.7 1</background>
      <shadows>true</shadows>
    </scene>
    <model name='ground_plane'>
      <static>true</static>
      <link name='link'>
        <collision name='collision'>
          <geometry>
            <plane>
              <normal>0 0 1</normal>
              <size>100 100</size>
            </plane>
          </geometry>
          <surface>
            <friction>
              <ode/>
            </friction>
            <bounce/>
            <contact/>
          </surface>
        </collision>
        <visual name='visual'>
          <geometry>
            <plane>
              <normal>0 0 1</normal>
              <size>100 100</size>
            </plane>
          </geometry>
          <material>
            <ambient>0.8 0.8 0.8 1</ambient>
            <diffuse>0.8 0.8 0.8 1</diffuse>
            <specular>0.8 0.8 0.8 1</specular>
          </material>
        </visual>
        <pose>0 0 0 0 -0 0</pose>
        <inertial>
          <pose>0 0 0 0 -0 0</pose>
          <mass>1</mass>
          <inertia>
            <ixx>1</ixx>
            <ixy>0</ixy>
            <ixz>0</ixz>
            <iyy>1</iyy>
            <iyz>0</iyz>
            <izz>1</izz>
          </inertia>
        </inertial>
        <enable_wind>false</enable_wind>
      </link>
      <pose>0 0 0 0 -0 0</pose>
      <self_collide>false</self_collide>
    </model>
    <model name='x3_0'>
      <pose>-0 -0 0.054632 0 -0 0</pose>
      <link name='X3_0/base_link'>
        <pose>0 0 0 0 -0 0</pose>
        <inertial>
          <pose>0 0 0 0 -0 0</pose>
          <mass>1.5</mass>
          <inertia>
            <ixx>0.034756299999999997</ixx>
            <ixy>0</ixy>
            <ixz>0</ixz>
            <iyy>0.070000000000000007</iyy>
            <iyz>0</iyz>
            <izz>0.097699999999999995</izz>
          </inertia>
        </inertial>
        <collision name='X3_0/base_link_inertia_collision'>
          <pose>0 0 0 0 -0 0</pose>
          <geometry>
            <box>
              <size>0.47 0.47 0.11</size>
            </box>
          </geometry>
          <surface>
            <friction>
              <ode/>
            </friction>
            <bounce/>
            <contact/>
          </surface>
        </collision>
        <visual name='X3_0/base_link_inertia_visual'>
          <pose>0 0 0 0 -0 0</pose>
          <geometry>
            <mesh>
              <scale>1 1 1</scale>
              <uri>x3_blue.dae</uri>
            </mesh>
          </geometry>
        </visual>
        <enable_wind>false</enable_wind>
      </link>
      <link name='X3_0/rotor_0'>
        <pose>0.13 -0.22 0.023 -0 -0 -0</pose>
        <inertial>
          <pose>0 0 0 0 -0 0</pose>
          <mass>0.0050000000000000001</mass>
          <inertia>
            <ixx>9.7499999999999998e-07</ixx>
            <ixy>0</ixy>
            <ixz>0</ixz>
            <iyy>4.1704099999999999e-05</iyy>
            <iyz>0</iyz>
            <izz>4.2604100000000001e-05</izz>
          </inertia>
        </inertial>
        <collision name='X3_0/rotor_0_collision'>
          <pose>0 0 0 0 -0 0</pose>
          <geometry>
            <cylinder>
              <length>0.0050000000000000001</length>
              <radius>0.10000000000000001</radius>
            </cylinder>
          </geometry>
          <surface>
            <contact>
              <ode/>
            </contact>
            <friction>
              <ode/>
            </friction>
            <bounce/>
          </surface>
        </collision>
        <visual name='X3_0/rotor_0_visual'>
          <pose>0 0 0 0 -0 0</pose>
          <geometry>
            <mesh>
              <scale>0.1 0.1 0.1</scale>
              <uri>https://fuel.gazebosim.org/1.0/openrobotics/models/x3 uav/4/files/meshes/propeller_ccw.dae</uri>
            </mesh>
          </geometry>
          <material>
            <script>
              <name>Gazebo/Blue</name>
              <uri>file://media/materials/scripts/gazebo.material</uri>
            </script>
          </material>
        </visual>
        <gravity>true</gravity>
        <velocity_decay/>
        <enable_wind>false</enable_wind>
      </link>
      <joint name='X3_0/rotor_0_joint' type='revolute'>
        <child>X3_0/rotor_0</child>
        <parent>X3_0/base_link</parent>
        <axis>
          <xyz>0 0 1</xyz>
          <limit>
            <lower>-10000000000000000</lower>
            <upper>10000000000000000</upper>
            <effort>inf</effort>
            <velocity>inf</velocity>
            <stiffness>100000000</stiffness>
            <dissipation>1</dissipation>
          </limit>
          <dynamics>
            <spring_reference>0</spring_reference>
            <spring_stiffness>0</spring_stiffness>
            <damping>0</damping>
            <friction>0</friction>
          </dynamics>
        </axis>
        <pose>0 0 0 0 -0 0</pose>
      </joint>
      <link name='X3_0/rotor_1'>
        <pose>-0.13 0.2 0.023 -0 -0 -0</pose>
        <inertial>
          <pose>0 0 0 0 -0 0</pose>
          <mass>0.0050000000000000001</mass>
          <inertia>
            <ixx>9.7499999999999998e-07</ixx>
            <ixy>0</ixy>
            <ixz>0</ixz>
            <iyy>4.1704099999999999e-05</iyy>
            <iyz>0</iyz>
            <izz>4.2604100000000001e-05</izz>
          </inertia>
        </inertial>
        <collision name='X3_0/rotor_1_collision'>
          <pose>0 0 0 0 -0 0</pose>
          <geometry>
            <cylinder>
              <length>0.0050000000000000001</length>
              <radius>0.10000000000000001</radius>
            </cylinder>
          </geometry>
          <surface>
            <contact>
              <ode/>
            </contact>
            <friction>
              <ode/>
            </friction>
            <bounce/>
          </surface>
        </collision>
        <visual name='X3_0/rotor_1_visual'>
          <pose>0 0 0 0 -0 0</pose>
          <geometry>
            <mesh>
              <scale>0.1 0.1 0.1</scale>
              <uri>https://fuel.gazebosim.org/1.0/openrobotics/models/x3 uav/4/files/meshes/propeller_ccw.dae</uri>
            </mesh>
          </geometry>
          <material>
            <script>
              <name>Gazebo/Red</name>
              <uri>file://media/materials/scripts/gazebo.material</uri>
            </script>
          </material>
        </visual>
        <gravity>true</gravity>
        <velocity_decay/>
        <enable_wind>false</enable_wind>
      </link>
      <joint name='X3_0/rotor_1_joint' type='revolute'>
        <child>X3_0/rotor_1</child>
        <parent>X3_0/base_link</parent>
        <axis>
          <xyz>0 0 1</xyz>
          <limit>
            <lower>-10000000000000000</lower>
            <upper>10000000000000000</upper>
            <effort>inf</effort>
            <velocity>inf</velocity>
            <stiffness>100000000</stiffness>
            <dissipation>1</dissipation>
          </limit>
          <dynamics>
            <spring_reference>0</spring_reference>
            <spring_stiffness>0</spring_stiffness>
            <damping>0</damping>
            <friction>0</friction>
          </dynamics>
        </axis>
        <pose>0 0 0 0 -0 0</pose>
      </joint>
      <link name='X3_0/rotor_2'>
        <pose>0.13 0.22 0.023 -0 -0 -0</pose>
        <inertial>
          <pose>0 0 0 0 -0 0</pose>
          <mass>0.0050000000000000001</mass>
          <inertia>
            <ixx>9.7499999999999998e-07</ixx>
            <ixy>0</ixy>
            <ixz>0</ixz>
            <iyy>4.1704099999999999e-05</iyy>
            <iyz>0</iyz>
            <izz>4.2604100000000001e-05</izz>
          </inertia>
        </inertial>
        <collision name='X3_0/rotor_2_collision'>
          <pose>0 0 0 0 -0 0</pose>
          <geometry>
            <cylinder>
              <length>0.0050000000000000001</length>
              <radius>0.10000000000000001</radius>
            </cylinder>
          </geometry>
          <surface>
            <contact>
              <ode/>
            </contact>
            <friction>
              <ode/>
            </friction>
            <bounce/>
          </surface>
        </collision>
        <visual name='X3_0/rotor_2_visual'>
          <pose>0 0 0 0 -0 0</pose>
          <geometry>
            <mesh>
              <scale>0.1 0.1 0.1</scale>
              <uri>https://fuel.gazebosim.org/1.0/openrobotics/models/x3 uav/4/files/meshes/propeller_cw.dae</uri>
            </mesh>
          </geometry>
          <material>
            <script>
              <name>Gazebo/Blue</name>
              <uri>file://media/materials/scripts/gazebo.material</uri>
            </script>
          </material>
        </visual>
        <gravity>true</gravity>
        <velocity_decay/>
        <enable_wind>false</enable_wind>
      </link>
      <joint name='X3_0/rotor_2_joint' type='revolute'>
        <child>X3_0/rotor_2</child>
        <parent>X3_0/base_link</parent>
        <axis>
          <xyz>0 0 1</xyz>
          <limit>
            <lower>-10000000000000000</lower>
            <upper>10000000000000000</upper>
            <effort>inf</effort>
            <velocity>inf</velocity>
            <stiffness>100000000</stiffness>
            <dissipation>1</dissipation>
          </limit>
          <dynamics>
            <spring_reference>0</spring_reference>
            <spring_stiffness>0</spring_stiffness>
            <damping>0</damping>
            <friction>0</friction>
          </dynamics>
        </axis>
        <pose>0 0 0 0 -0 0</pose>
      </joint>
      <link name='X3_0/rotor_3'>
        <pose>-0.13 -0.2 0.023 -0 -0 -0</pose>
        <inertial>
          <pose>0 0 0 0 -0 0</pose>
          <mass>0.0050000000000000001</mass>
          <inertia>
            <ixx>9.7499999999999998e-07</ixx>
            <ixy>0</ixy>
            <ixz>0</ixz>
            <iyy>4.1704099999999999e-05</iyy>
            <iyz>0</iyz>
            <izz>4.2604100000000001e-05</izz>
          </inertia>
        </inertial>
        <collision name='X3_0/rotor_3_collision'>
          <pose>0 0 0 0 -0 0</pose>
          <geometry>
            <cylinder>
              <length>0.0050000000000000001</length>
              <radius>0.10000000000000001</radius>
            </cylinder>
          </geometry>
          <surface>
            <contact>
              <ode/>
            </contact>
            <friction>
              <ode/>
            </friction>
            <bounce/>
          </surface>
        </collision>
        <visual name='X3_0/rotor_3_visual'>
          <pose>0 0 0 0 -0 0</pose>
          <geometry>
            <mesh>
              <scale>0.1 0.1 0.1</scale>
              <uri>https://fuel.gazebosim.org/1.0/openrobotics/models/x3 uav/4/files/meshes/propeller_cw.dae</uri>
            </mesh>
          </geometry>
          <material>
            <script>
              <name>Gazebo/Red</name>
              <uri>file://media/materials/scripts/gazebo.material</uri>
            </script>
          </material>
        </visual>
        <gravity>true</gravity>
        <velocity_decay/>
        <enable_wind>false</enable_wind>
      </link>
      <joint name='X3_0/rotor_3_joint' type='revolute'>
        <child>X3_0/rotor_3</child>
        <parent>X3_0/base_link</parent>
        <axis>
          <xyz>0 0 1</xyz>
          <limit>
            <lower>-10000000000000000</lower>
            <upper>10000000000000000</upper>
            <effort>inf</effort>
            <velocity>inf</velocity>
            <stiffness>100000000</stiffness>
            <dissipation>1</dissipation>
          </limit>
          <dynamics>
            <spring_reference>0</spring_reference>
            <spring_stiffness>0</spring_stiffness>
            <damping>0</damping>
            <friction>0</friction>
          </dynamics>
        </axis>
        <pose>0 0 0 0 -0 0</pose>
      </joint>
      <plugin name='ignition::gazebo::systems::MulticopterMotorModel' filename='ignition-gazebo-multicopter-motor-model-system'>
        <robotNamespace>X3_0</robotNamespace>
        <jointName>X3_0/rotor_0_joint</jointName>
        <linkName>X3_0/rotor_0</linkName>
        <turningDirection>ccw</turningDirection>
        <timeConstantUp>0.0125</timeConstantUp>
        <timeConstantDown>0.025</timeConstantDown>
        <maxRotVelocity>800.0</maxRotVelocity>
        <motorConstant>8.54858e-06</motorConstant>
        <momentConstant>0.016</momentConstant>
        <commandSubTopic>gazebo/command/motor_speed</commandSubTopic>
        <motorNumber>0</motorNumber>
        <rotorDragCoefficient>8.06428e-05</rotorDragCoefficient>
        <rollingMomentCoefficient>1e-06</rollingMomentCoefficient>
        <motorSpeedPubTopic>motor_speed/0</motorSpeedPubTopic>
        <rotorVelocitySlowdownSim>10</rotorVelocitySlowdownSim>
        <motorType>velocity</motorType>
      </plugin>
      <plugin name='ignition::gazebo::systems::MulticopterMotorModel' filename='ignition-gazebo-multicopter-motor-model-system'>
        <robotNamespace>X3_0</robotNamespace>
        <jointName>X3_0/rotor_1_joint</jointName>
        <linkName>X3_0/rotor_1</linkName>
        <turningDirection>ccw</turningDirection>
        <timeConstantUp>0.0125</timeConstantUp>
        <timeConstantDown>0.025</timeConstantDown>
        <maxRotVelocity>800.0</maxRotVelocity>
        <motorConstant>8.54858e-06</motorConstant>
        <momentConstant>0.016</momentConstant>
        <commandSubTopic>gazebo/command/motor_speed</commandSubTopic>
        <motorNumber>1</motorNumber>
        <rotorDragCoefficient>8.06428e-05</rotorDragCoefficient>
        <rollingMomentCoefficient>1e-06</rollingMomentCoefficient>
        <motorSpeedPubTopic>motor_speed/1</motorSpeedPubTopic>
        <rotorVelocitySlowdownSim>10</rotorVelocitySlowdownSim>
        <motorType>velocity</motorType>
      </plugin>
      <plugin name='ignition::gazebo::systems::MulticopterMotorModel' filename='ignition-gazebo-multicopter-motor-model-system'>
        <robotNamespace>X3_0</robotNamespace>
        <jointName>X3_0/rotor_2_joint</jointName>
        <linkName>X3_0/rotor_2</linkName>
        <turningDirection>cw</turningDirection>
        <timeConstantUp>0.0125</timeConstantUp>
        <timeConstantDown>0.025</timeConstantDown>
        <maxRotVelocity>800.0</maxRotVelocity>
        <motorConstant>8.54858e-06</motorConstant>
        <momentConstant>0.016</momentConstant>
        <commandSubTopic>gazebo/command/motor_speed</commandSubTopic>
        <motorNumber>2</motorNumber>
        <rotorDragCoefficient>8.06428e-05</rotorDragCoefficient>
        <rollingMomentCoefficient>1e-06</rollingMomentCoefficient>
        <motorSpeedPubTopic>motor_speed/2</motorSpeedPubTopic>
        <rotorVelocitySlowdownSim>10</rotorVelocitySlowdownSim>
        <motorType>velocity</motorType>
      </plugin>
      <plugin name='ignition::gazebo::systems::MulticopterMotorModel' filename='ignition-gazebo-multicopter-motor-model-system'>
        <robotNamespace>X3_0</robotNamespace>
        <jointName>X3_0/rotor_3_joint</jointName>
        <linkName>X3_0/rotor_3</linkName>
        <turningDirection>cw</turningDirection>
        <timeConstantUp>0.0125</timeConstantUp>
        <timeConstantDown>0.025</timeConstantDown>
        <maxRotVelocity>800.0</maxRotVelocity>
        <motorConstant>8.54858e-06</motorConstant>
        <momentConstant>0.016</momentConstant>
        <commandSubTopic>gazebo/command/motor_speed</commandSubTopic>
        <motorNumber>3</motorNumber>
        <rotorDragCoefficient>8.06428e-05</rotorDragCoefficient>
        <rollingMomentCoefficient>1e-06</rollingMomentCoefficient>
        <motorSpeedPubTopic>motor_speed/3</motorSpeedPubTopic>
        <rotorVelocitySlowdownSim>10</rotorVelocitySlowdownSim>
        <motorType>velocity</motorType>
      </plugin>
      <plugin name='ignition::gazebo::systems::MulticopterVelocityControl' filename='ignition-gazebo-multicopter-control-system'>
        <robotNamespace>X3_0</robotNamespace>
        <enableSubTopic>enable</enableSubTopic>
        <comLinkName>X3_0/base_link</comLinkName>
        <velocityGain>2.7 2.7 2.7</velocityGain>
        <attitudeGain>2 3 0.15</attitudeGain>
        <angularRateGain>0.4 0.52 0.18</angularRateGain>
        <maximumLinearAcceleration>2 2 2</maximumLinearAcceleration>
        <maximumLinearVelocity>1 1 1</maximumLinearVelocity>
        <rotorConfiguration>
          <rotor>
            <jointName>X3_0/rotor_0_joint</jointName>
            <forceConstant>8.54858e-06</forceConstant>
            <momentConstant>0.016</momentConstant>
            <direction>1</direction>
          </rotor>
          <rotor>
            <jointName>X3_0/rotor_1_joint</jointName>
            <forceConstant>8.54858e-06</forceConstant>
            <momentConstant>0.016</momentConstant>
            <direction>1</direction>
          </rotor>
          <rotor>
            <jointName>X3_0/rotor_2_joint</jointName>
            <forceConstant>8.54858e-06</forceConstant>
            <momentConstant>0.016</momentConstant>
            <direction>-1</direction>
          </rotor>
          <rotor>
            <jointName>X3_0/rotor_3_joint</jointName>
            <forceConstant>8.54858e-06</forceConstant>
            <momentConstant>0.016</momentConstant>
            <direction>-1</direction>
          </rotor>
        </rotorConfiguration>
      </plugin>
      <plugin name='ignition::gazebo::systems::OdometryPublisher' filename='ignition-gazebo-odometry-publisher-system'>
        <odom_topic>/X3_0/odometry</odom_topic>
        <dimensions>3</dimensions>
      </plugin>
      <static>false</static>
      <self_collide>false</self_collide>
    </model>
    <model name='x3_1'>
      <pose>0 -2 0.054632 0 -0 0</pose>
      <link name='X3_1/base_link'>
        <pose>0 0 0 0 -0 0</pose>
        <inertial>
          <pose>0 0 0 0 -0 0</pose>
          <mass>1.5</mass>
          <inertia>
            <ixx>0.034756299999999997</ixx>
            <ixy>0</ixy>
            <ixz>0</ixz>
            <iyy>0.070000000000000007</iyy>
            <iyz>0</iyz>
            <izz>0.097699999999999995</izz>
          </inertia>
        </inertial>
        <collision name='X3_1/base_link_inertia_collision'>
          <pose>0 0 0 0 -0 0</pose>
          <geometry>
            <box>
              <size>0.47 0.47 0.11</size>
            </box>
          </geometry>
          <surface>
            <friction>
              <ode/>
            </friction>
            <bounce/>
            <contact/>
          </surface>
        </collision>
        <visual name='X3_1/base_link_inertia_visual'>
          <pose>0 0 0 0 -0 0</pose>
          <geometry>
            <mesh>
              <scale>1 1 1</scale>
              <uri>x3_red.dae</uri>
            </mesh>
          </geometry>
        </visual>
        <enable_wind>false</enable_wind>
      </link>
      <link name='X3_1/rotor_0'>
        <pose>0.13 -0.22 0.023 -0 -0 -0</pose>
        <inertial>
          <pose>0 0 0 0 -0 0</pose>
          <mass>0.0050000000000000001</mass>
          <inertia>
            <ixx>9.7499999999999998e-07</ixx>
            <ixy>0</ixy>
            <ixz>0</ixz>
            <iyy>4.1704099999999999e-05</iyy>
            <iyz>0</iyz>
            <izz>4.2604100000000001e-05</izz>
          </inertia>
        </inertial>
        <collision name='X3_1/rotor_0_collision'>
          <pose>0 0 0 0 -0 0</pose>
          <geometry>
            <cylinder>
              <length>0.0050000000000000001</length>
              <radius>0.10000000000000001</radius>
            </cylinder>
          </geometry>
          <surface>
            <contact>
              <ode/>
            </contact>
            <friction>
              <ode/>
            </friction>
            <bounce/>
          </surface>
        </collision>
        <visual name='X3_1/rotor_0_visual'>
          <pose>0 0 0 0 -0 0</pose>
          <geometry>
            <mesh>
              <scale>0.1 0.1 0.1</scale>
              <uri>https://fuel.gazebosim.org/1.0/openrobotics/models/x3 uav/4/files/meshes/propeller_ccw.dae</uri>
            </mesh>
          </geometry>
          <material>
            <script>
              <name>Gazebo/Blue</name>
              <uri>file://media/materials/scripts/gazebo.material</uri>
            </script>
          </material>
        </visual>
        <gravity>true</gravity>
        <velocity_decay/>
        <enable_wind>false</enable_wind>
      </link>
      <joint name='X3_1/rotor_0_joint' type='revolute'>
        <child>X3_1/rotor_0</child>
        <parent>X3_1/base_link</parent>
        <axis>
          <xyz>0 0 1</xyz>
          <limit>
            <lower>-10000000000000000</lower>
            <upper>10000000000000000</upper>
            <effort>inf</effort>
            <velocity>inf</velocity>
            <stiffness>100000000</stiffness>
            <dissipation>1</dissipation>
          </limit>
          <dynamics>
            <spring_reference>0</spring_reference>
            <spring_stiffness>0</spring_stiffness>
            <damping>0</damping>
            <friction>0</friction>
          </dynamics>
        </axis>
        <pose>0 0 0 0 -0 0</pose>
      </joint>
      <link name='X3_1/rotor_1'>
        <pose>-0.13 0.2 0.023 -0 -0 -0</pose>
        <inertial>
          <pose>0 0 0 0 -0 0</pose>
          <mass>0.0050000000000000001</mass>
          <inertia>
            <ixx>9.7499999999999998e-07</ixx>
            <ixy>0</ixy>
            <ixz>0</ixz>
            <iyy>4.1704099999999999e-05</iyy>
            <iyz>0</iyz>
            <izz>4.2604100000000001e-05</izz>
          </inertia>
        </inertial>
        <collision name='X3_1/rotor_1_collision'>
          <pose>0 0 0 0 -0 0</pose>
          <geometry>
            <cylinder>
              <length>0.0050000000000000001</length>
              <radius>0.10000000000000001</radius>
            </cylinder>
          </geometry>
          <surface>
            <contact>
              <ode/>
            </contact>
            <friction>
              <ode/>
            </friction>
            <bounce/>
          </surface>
        </collision>
        <visual name='X3_1/rotor_1_visual'>
          <pose>0 0 0 0 -0 0</pose>
          <geometry>
            <mesh>
              <scale>0.1 0.1 0.1</scale>
              <uri>https://fuel.gazebosim.org/1.0/openrobotics/models/x3 uav/4/files/meshes/propeller_ccw.dae</uri>
            </mesh>
          </geometry>
          <material>
            <script>
              <name>Gazebo/Red</name>
              <uri>file://media/materials/scripts/gazebo.material</uri>
            </script>
          </material>
        </visual>
        <gravity>true</gravity>
        <velocity_decay/>
        <enable_wind>false</enable_wind>
      </link>
      <joint name='X3_1/rotor_1_joint' type='revolute'>
        <child>X3_1/rotor_1</child>
        <parent>X3_1/base_link</parent>
        <axis>
          <xyz>0 0 1</xyz>
          <limit>
            <lower>-10000000000000000</lower>
            <upper>10000000000000000</upper>
            <effort>inf</effort>
            <velocity>inf</velocity>
            <stiffness>100000000</stiffness>
            <dissipation>1</dissipation>
          </limit>
          <dynamics>
            <spring_reference>0</spring_reference>
            <spring_stiffness>0</spring_stiffness>
            <damping>0</damping>
            <friction>0</friction>
          </dynamics>
        </axis>
        <pose>0 0 0 0 -0 0</pose>
      </joint>
      <link name='X3_1/rotor_2'>
        <pose>0.13 0.22 0.023 -0 -0 -0</pose>
        <inertial>
          <pose>0 0 0 0 -0 0</pose>
          <mass>0.0050000000000000001</mass>
          <inertia>
            <ixx>9.7499999999999998e-07</ixx>
            <ixy>0</ixy>
            <ixz>0</ixz>
            <iyy>4.1704099999999999e-05</iyy>
            <iyz>0</iyz>
            <izz>4.2604100000000001e-05</izz>
          </inertia>
        </inertial>
        <collision name='X3_1/rotor_2_collision'>
          <pose>0 0 0 0 -0 0</pose>
          <geometry>
            <cylinder>
              <length>0.0050000000000000001</length>
              <radius>0.10000000000000001</radius>
            </cylinder>
          </geometry>
          <surface>
            <contact>
              <ode/>
            </contact>
            <friction>
              <ode/>
            </friction>
            <bounce/>
          </surface>
        </collision>
        <visual name='X3_1/rotor_2_visual'>
          <pose>0 0 0 0 -0 0</pose>
          <geometry>
            <mesh>
              <scale>0.1 0.1 0.1</scale>
              <uri>https://fuel.gazebosim.org/1.0/openrobotics/models/x3 uav/4/files/meshes/propeller_cw.dae</uri>
            </mesh>
          </geometry>
          <material>
            <script>
              <name>Gazebo/Blue</name>
              <uri>file://media/materials/scripts/gazebo.material</uri>
            </script>
          </material>
        </visual>
        <gravity>true</gravity>
        <velocity_decay/>
        <enable_wind>false</enable_wind>
      </link>
      <joint name='X3_1/rotor_2_joint' type='revolute'>
        <child>X3_1/rotor_2</child>
        <parent>X3_1/base_link</parent>
        <axis>
          <xyz>0 0 1</xyz>
          <limit>
            <lower>-10000000000000000</lower>
            <upper>10000000000000000</upper>
            <effort>inf</effort>
            <velocity>inf</velocity>
            <stiffness>100000000</stiffness>
            <dissipation>1</dissipation>
          </limit>
          <dynamics>
            <spring_reference>0</spring_reference>
            <spring_stiffness>0</spring_stiffness>
            <damping>0</damping>
            <friction>0</friction>
          </dynamics>
        </axis>
        <pose>0 0 0 0 -0 0</pose>
      </joint>
      <link name='X3_1/rotor_3'>
        <pose>-0.13 -0.2 0.023 -0 -0 -0</pose>
        <inertial>
          <pose>0 0 0 0 -0 0</pose>
          <mass>0.0050000000000000001</mass>
          <inertia>
            <ixx>9.7499999999999998e-07</ixx>
            <ixy>0</ixy>
            <ixz>0</ixz>
            <iyy>4.1704099999999999e-05</iyy>
            <iyz>0</iyz>
            <izz>4.2604100000000001e-05</izz>
          </inertia>
        </inertial>
        <collision name='X3_1/rotor_3_collision'>
          <pose>0 0 0 0 -0 0</pose>
          <geometry>
            <cylinder>
              <length>0.0050000000000000001</length>
              <radius>0.10000000000000001</radius>
            </cylinder>
          </geometry>
          <surface>
            <contact>
              <ode/>
            </contact>
            <friction>
              <ode/>
            </friction>
            <bounce/>
          </surface>
        </collision>
        <visual name='X3_1/rotor_3_visual'>
          <pose>0 0 0 0 -0 0</pose>
          <geometry>
            <mesh>
              <scale>0.1 0.1 0.1</scale>
              <uri>https://fuel.gazebosim.org/1.0/openrobotics/models/x3 uav/4/files/meshes/propeller_cw.dae</uri>
            </mesh>
          </geometry>
          <material>
            <script>
              <name>Gazebo/Red</name>
              <uri>file://media/materials/scripts/gazebo.material</uri>
            </script>
          </material>
        </visual>
        <gravity>true</gravity>
        <velocity_decay/>
        <enable_wind>false</enable_wind>
      </link>
      <joint name='X3_1/rotor_3_joint' type='revolute'>
        <child>X3_1/rotor_3</child>
        <parent>X3_1/base_link</parent>
        <axis>
          <xyz>0 0 1</xyz>
          <limit>
            <lower>-10000000000000000</lower>
            <upper>10000000000000000</upper>
            <effort>inf</effort>
            <velocity>inf</velocity>
            <stiffness>100000000</stiffness>
            <dissipation>1</dissipation>
          </limit>
          <dynamics>
            <spring_reference>0</spring_reference>
            <spring_stiffness>0</spring_stiffness>
            <damping>0</damping>
            <friction>0</friction>
          </dynamics>
        </axis>
        <pose>0 0 0 0 -0 0</pose>
      </joint>
      <plugin name='ignition::gazebo::systems::MulticopterMotorModel' filename='ignition-gazebo-multicopter-motor-model-system'>
        <robotNamespace>X3_1</robotNamespace>
        <jointName>X3_1/rotor_0_joint</jointName>
        <linkName>X3_1/rotor_0</linkName>
        <turningDirection>ccw</turningDirection>
        <timeConstantUp>0.0125</timeConstantUp>
        <timeConstantDown>0.025</timeConstantDown>
        <maxRotVelocity>800.0</maxRotVelocity>
        <motorConstant>8.54858e-06</motorConstant>
        <momentConstant>0.016</momentConstant>
        <commandSubTopic>gazebo/command/motor_speed</commandSubTopic>
        <motorNumber>0</motorNumber>
        <rotorDragCoefficient>8.06428e-05</rotorDragCoefficient>
        <rollingMomentCoefficient>1e-06</rollingMomentCoefficient>
        <motorSpeedPubTopic>motor_speed/0</motorSpeedPubTopic>
        <rotorVelocitySlowdownSim>10</rotorVelocitySlowdownSim>
        <motorType>velocity</motorType>
      </plugin>
      <plugin name='ignition::gazebo::systems::MulticopterMotorModel' filename='ignition-gazebo-multicopter-motor-model-system'>
        <robotNamespace>X3_1</robotNamespace>
        <jointName>X3_1/rotor_1_joint</jointName>
        <linkName>X3_1/rotor_1</linkName>
        <turningDirection>ccw</turningDirection>
        <timeConstantUp>0.0125</timeConstantUp>
        <timeConstantDown>0.025</timeConstantDown>
        <maxRotVelocity>800.0</maxRotVelocity>
        <motorConstant>8.54858e-06</motorConstant>
        <momentConstant>0.016</momentConstant>
        <commandSubTopic>gazebo/command/motor_speed</commandSubTopic>
        <motorNumber>1</motorNumber>
        <rotorDragCoefficient>8.06428e-05</rotorDragCoefficient>
        <rollingMomentCoefficient>1e-06</rollingMomentCoefficient>
        <motorSpeedPubTopic>motor_speed/1</motorSpeedPubTopic>
        <rotorVelocitySlowdownSim>10</rotorVelocitySlowdownSim>
        <motorType>velocity</motorType>
      </plugin>
      <plugin name='ignition::gazebo::systems::MulticopterMotorModel' filename='ignition-gazebo-multicopter-motor-model-system'>
        <robotNamespace>X3_1</robotNamespace>
        <jointName>X3_1/rotor_2_joint</jointName>
        <linkName>X3_1/rotor_2</linkName>
        <turningDirection>cw</turningDirection>
        <timeConstantUp>0.0125</timeConstantUp>
        <timeConstantDown>0.025</timeConstantDown>
        <maxRotVelocity>800.0</maxRotVelocity>
        <motorConstant>8.54858e-06</motorConstant>
        <momentConstant>0.016</momentConstant>
        <commandSubTopic>gazebo/command/motor_speed</commandSubTopic>
        <motorNumber>2</motorNumber>
        <rotorDragCoefficient>8.06428e-05</rotorDragCoefficient>
        <rollingMomentCoefficient>1e-06</rollingMomentCoefficient>
        <motorSpeedPubTopic>motor_speed/2</motorSpeedPubTopic>
        <rotorVelocitySlowdownSim>10</rotorVelocitySlowdownSim>
        <motorType>velocity</motorType>
      </plugin>
      <plugin name='ignition::gazebo::systems::MulticopterMotorModel' filename='ignition-gazebo-multicopter-motor-model-system'>
        <robotNamespace>X3_1</robotNamespace>
        <jointName>X3_1/rotor_3_joint</jointName>
        <linkName>X3_1/rotor_3</linkName>
        <turningDirection>cw</turningDirection>
        <timeConstantUp>0.0125</timeConstantUp>
        <timeConstantDown>0.025</timeConstantDown>
        <maxRotVelocity>800.0</maxRotVelocity>
        <motorConstant>8.54858e-06</motorConstant>
        <momentConstant>0.016</momentConstant>
        <commandSubTopic>gazebo/command/motor_speed</commandSubTopic>
        <motorNumber>3</motorNumber>
        <rotorDragCoefficient>8.06428e-05</rotorDragCoefficient>
        <rollingMomentCoefficient>1e-06</rollingMomentCoefficient>
        <motorSpeedPubTopic>motor_speed/3</motorSpeedPubTopic>
        <rotorVelocitySlowdownSim>10</rotorVelocitySlowdownSim>
        <motorType>velocity</motorType>
      </plugin>
      <plugin name='ignition::gazebo::systems::MulticopterVelocityControl' filename='ignition-gazebo-multicopter-control-system'>
        <robotNamespace>X3_1</robotNamespace>
        <enableSubTopic>enable</enableSubTopic>
        <comLinkName>X3_1/base_link</comLinkName>
        <velocityGain>2.7 2.7 2.7</velocityGain>
        <attitudeGain>2 3 0.15</attitudeGain>
        <angularRateGain>0.4 0.52 0.18</angularRateGain>
        <maximumLinearAcceleration>2 2 2</maximumLinearAcceleration>
        <maximumLinearVelocity>1 1 1</maximumLinearVelocity>
        <rotorConfiguration>
          <rotor>
            <jointName>X3_1/rotor_0_joint</jointName>
            <forceConstant>8.54858e-06</forceConstant>
            <momentConstant>0.016</momentConstant>
            <direction>1</direction>
          </rotor>
          <rotor>
            <jointName>X3_1/rotor_1_joint</jointName>
            <forceConstant>8.54858e-06</forceConstant>
            <momentConstant>0.016</momentConstant>
            <direction>1</direction>
          </rotor>
          <rotor>
            <jointName>X3_1/rotor_2_joint</jointName>
            <forceConstant>8.54858e-06</forceConstant>
            <momentConstant>0.016</momentConstant>
            <direction>-1</direction>
          </rotor>
          <rotor>
            <jointName>X3_1/rotor_3_joint</jointName>
            <forceConstant>8.54858e-06</forceConstant>
            <momentConstant>0.016</momentConstant>
            <direction>-1</direction>
          </rotor>
        </rotorConfiguration>
      </plugin>
      <plugin name='ignition::gazebo::systems::OdometryPublisher' filename='ignition-gazebo-odometry-publisher-system'>
        <odom_topic>/X3_1/odometry</odom_topic>
        <dimensions>3</dimensions>
      </plugin>
      <static>false</static>
      <self_collide>false</self_collide>
    </model>
    <model name='x3_2'>
      <pose>-0 2 0.054632 0 -0 0</pose>
      <link name='X3_2/base_link'>
        <pose>0 0 0 0 -0 0</pose>
        <inertial>
          <pose>0 0 0 0 -0 0</pose>
          <mass>1.5</mass>
          <inertia>
            <ixx>0.034756299999999997</ixx>
            <ixy>0</ixy>
            <ixz>0</ixz>
            <iyy>0.070000000000000007</iyy>
            <iyz>0</iyz>
            <izz>0.097699999999999995</izz>
          </inertia>
        </inertial>
        <collision name='X3_2/base_link_inertia_collision'>
          <pose>0 0 0 0 -0 0</pose>
          <geometry>
            <box>
              <size>0.47 0.47 0.11</size>
            </box>
          </geometry>
          <surface>
            <friction>
              <ode/>
            </friction>
            <bounce/>
            <contact/>
          </surface>
        </collision>
        <visual name='X3_2/base_link_inertia_visual'>
          <pose>0 0 0 0 -0 0</pose>
          <geometry>
            <mesh>
              <scale>1 1 1</scale>
              <uri>x3_blue.dae</uri>
            </mesh>
          </geometry>
        </visual>
        <enable_wind>false</enable_wind>
      </link>
      <link name='X3_2/rotor_0'>
        <pose>0.13 -0.22 0.023 -0 -0 -0</pose>
        <inertial>
          <pose>0 0 0 0 -0 0</pose>
          <mass>0.0050000000000000001</mass>
          <inertia>
            <ixx>9.7499999999999998e-07</ixx>
            <ixy>0</ixy>
            <ixz>0</ixz>
            <iyy>4.1704099999999999e-05</iyy>
            <iyz>0</iyz>
            <izz>4.2604100000000001e-05</izz>
          </inertia>
        </inertial>
        <collision name='X3_2/rotor_0_collision'>
          <pose>0 0 0 0 -0 0</pose>
          <geometry>
            <cylinder>
              <length>0.0050000000000000001</length>
              <radius>0.10000000000000001</radius>
            </cylinder>
          </geometry>
          <surface>
            <contact>
              <ode/>
            </contact>
            <friction>
              <ode/>
            </friction>
            <bounce/>
          </surface>
        </collision>
        <visual name='X3_2/rotor_0_visual'>
          <pose>0 0 0 0 -0 0</pose>
          <geometry>
            <mesh>
              <scale>0.1 0.1 0.1</scale>
              <uri>https://fuel.gazebosim.org/1.0/openrobotics/models/x3 uav/4/files/meshes/propeller_ccw.dae</uri>
            </mesh>
          </geometry>
          <material>
            <script>
              <name>Gazebo/Blue</name>
              <uri>file://media/materials/scripts/gazebo.material</uri>
            </script>
          </material>
        </visual>
        <gravity>true</gravity>
        <velocity_decay/>
        <enable_wind>false</enable_wind>
      </link>
      <joint name='X3_2/rotor_0_joint' type='revolute'>
        <child>X3_2/rotor_0</child>
        <parent>X3_2/base_link</parent>
        <axis>
          <xyz>0 0 1</xyz>
          <limit>
            <lower>-10000000000000000</lower>
            <upper>10000000000000000</upper>
            <effort>inf</effort>
            <velocity>inf</velocity>
            <stiffness>100000000</stiffness>
            <dissipation>1</dissipation>
          </limit>
          <dynamics>
            <spring_reference>0</spring_reference>
            <spring_stiffness>0</spring_stiffness>
            <damping>0</damping>
            <friction>0</friction>
          </dynamics>
        </axis>
        <pose>0 0 0 0 -0 0</pose>
      </joint>
      <link name='X3_2/rotor_1'>
        <pose>-0.13 0.2 0.023 -0 -0 -0</pose>
        <inertial>
          <pose>0 0 0 0 -0 0</pose>
          <mass>0.0050000000000000001</mass>
          <inertia>
            <ixx>9.7499999999999998e-07</ixx>
            <ixy>0</ixy>
            <ixz>0</ixz>
            <iyy>4.1704099999999999e-05</iyy>
            <iyz>0</iyz>
            <izz>4.2604100000000001e-05</izz>
          </inertia>
        </inertial>
        <collision name='X3_2/rotor_1_collision'>
          <pose>0 0 0 0 -0 0</pose>
          <geometry>
            <cylinder>
              <length>0.0050000000000000001</length>
              <radius>0.10000000000000001</radius>
            </cylinder>
          </geometry>
          <surface>
            <contact>
              <ode/>
            </contact>
            <friction>
              <ode/>
            </friction>
            <bounce/>
          </surface>
        </collision>
        <visual name='X3_2/rotor_1_visual'>
          <pose>0 0 0 0 -0 0</pose>
          <geometry>
            <mesh>
              <scale>0.1 0.1 0.1</scale>
              <uri>https://fuel.gazebosim.org/1.0/openrobotics/models/x3 uav/4/files/meshes/propeller_ccw.dae</uri>
            </mesh>
          </geometry>
          <material>
            <script>
              <name>Gazebo/Red</name>
              <uri>file://media/materials/scripts/gazebo.material</uri>
            </script>
          </material>
        </visual>
        <gravity>true</gravity>
        <velocity_decay/>
        <enable_wind>false</enable_wind>
      </link>
      <joint name='X3_2/rotor_1_joint' type='revolute'>
        <child>X3_2/rotor_1</child>
        <parent>X3_2/base_link</parent>
        <axis>
          <xyz>0 0 1</xyz>
          <limit>
            <lower>-10000000000000000</lower>
            <upper>10000000000000000</upper>
            <effort>inf</effort>
            <velocity>inf</velocity>
            <stiffness>100000000</stiffness>
            <dissipation>1</dissipation>
          </limit>
          <dynamics>
            <spring_reference>0</spring_reference>
            <spring_stiffness>0</spring_stiffness>
            <damping>0</damping>
            <friction>0</friction>
          </dynamics>
        </axis>
        <pose>0 0 0 0 -0 0</pose>
      </joint>
      <link name='X3_2/rotor_2'>
        <pose>0.13 0.22 0.023 -0 -0 -0</pose>
        <inertial>
          <pose>0 0 0 0 -0 0</pose>
          <mass>0.0050000000000000001</mass>
          <inertia>
            <ixx>9.7499999999999998e-07</ixx>
            <ixy>0</ixy>
            <ixz>0</ixz>
            <iyy>4.1704099999999999e-05</iyy>
            <iyz>0</iyz>
            <izz>4.2604100000000001e-05</izz>
          </inertia>
        </inertial>
        <collision name='X3_2/rotor_2_collision'>
          <pose>0 0 0 0 -0 0</pose>
          <geometry>
            <cylinder>
              <length>0.0050000000000000001</length>
              <radius>0.10000000000000001</radius>
            </cylinder>
          </geometry>
          <surface>
            <contact>
              <ode/>
            </contact>
            <friction>
              <ode/>
            </friction>
            <bounce/>
          </surface>
        </collision>
        <visual name='X3_2/rotor_2_visual'>
          <pose>0 0 0 0 -0 0</pose>
          <geometry>
            <mesh>
              <scale>0.1 0.1 0.1</scale>
              <uri>https://fuel.gazebosim.org/1.0/openrobotics/models/x3 uav/4/files/meshes/propeller_cw.dae</uri>
            </mesh>
          </geometry>
          <material>
            <script>
              <name>Gazebo/Blue</name>
              <uri>file://media/materials/scripts/gazebo.material</uri>
            </script>
          </material>
        </visual>
        <gravity>true</gravity>
        <velocity_decay/>
        <enable_wind>false</enable_wind>
      </link>
      <joint name='X3_2/rotor_2_joint' type='revolute'>
        <child>X3_2/rotor_2</child>
        <parent>X3_2/base_link</parent>
        <axis>
          <xyz>0 0 1</xyz>
          <limit>
            <lower>-10000000000000000</lower>
            <upper>10000000000000000</upper>
            <effort>inf</effort>
            <velocity>inf</velocity>
            <stiffness>100000000</stiffness>
            <dissipation>1</dissipation>
          </limit>
          <dynamics>
            <spring_reference>0</spring_reference>
            <spring_stiffness>0</spring_stiffness>
            <damping>0</damping>
            <friction>0</friction>
          </dynamics>
        </axis>
        <pose>0 0 0 0 -0 0</pose>
      </joint>
      <link name='X3_2/rotor_3'>
        <pose>-0.13 -0.2 0.023 -0 -0 -0</pose>
        <inertial>
          <pose>0 0 0 0 -0 0</pose>
          <mass>0.0050000000000000001</mass>
          <inertia>
            <ixx>9.7499999999999998e-07</ixx>
            <ixy>0</ixy>
            <ixz>0</ixz>
            <iyy>4.1704099999999999e-05</iyy>
            <iyz>0</iyz>
            <izz>4.2604100000000001e-05</izz>
          </inertia>
        </inertial>
        <collision name='X3_2/rotor_3_collision'>
          <pose>0 0 0 0 -0 0</pose>
          <geometry>
            <cylinder>
              <length>0.0050000000000000001</length>
              <radius>0.10000000000000001</radius>
            </cylinder>
          </geometry>
          <surface>
            <contact>
              <ode/>
            </contact>
            <friction>
              <ode/>
            </friction>
            <bounce/>
          </surface>
        </collision>
        <visual name='X3_2/rotor_3_visual'>
          <pose>0 0 0 0 -0 0</pose>
          <geometry>
            <mesh>
              <scale>0.1 0.1 0.1</scale>
              <uri>https://fuel.gazebosim.org/1.0/openrobotics/models/x3 uav/4/files/meshes/propeller_cw.dae</uri>
            </mesh>
          </geometry>
          <material>
            <script>
              <name>Gazebo/Red</name>
              <uri>file://media/materials/scripts/gazebo.material</uri>
            </script>
          </material>
        </visual>
        <gravity>true</gravity>
        <velocity_decay/>
        <enable_wind>false</enable_wind>
      </link>
      <joint name='X3_2/rotor_3_joint' type='revolute'>
        <child>X3_2/rotor_3</child>
        <parent>X3_2/base_link</parent>
        <axis>
          <xyz>0 0 1</xyz>
          <limit>
            <lower>-10000000000000000</lower>
            <upper>10000000000000000</upper>
            <effort>inf</effort>
            <velocity>inf</velocity>
            <stiffness>100000000</stiffness>
            <dissipation>1</dissipation>
          </limit>
          <dynamics>
            <spring_reference>0</spring_reference>
            <spring_stiffness>0</spring_stiffness>
            <damping>0</damping>
            <friction>0</friction>
          </dynamics>
        </axis>
        <pose>0 0 0 0 -0 0</pose>
      </joint>
      <plugin name='ignition::gazebo::systems::MulticopterMotorModel' filename='ignition-gazebo-multicopter-motor-model-system'>
        <robotNamespace>X3_2</robotNamespace>
        <jointName>X3_2/rotor_0_joint</jointName>
        <linkName>X3_2/rotor_0</linkName>
        <turningDirection>ccw</turningDirection>
        <timeConstantUp>0.0125</timeConstantUp>
        <timeConstantDown>0.025</timeConstantDown>
        <maxRotVelocity>800.0</maxRotVelocity>
        <motorConstant>8.54858e-06</motorConstant>
        <momentConstant>0.016</momentConstant>
        <commandSubTopic>gazebo/command/motor_speed</commandSubTopic>
        <motorNumber>0</motorNumber>
        <rotorDragCoefficient>8.06428e-05</rotorDragCoefficient>
        <rollingMomentCoefficient>1e-06</rollingMomentCoefficient>
        <motorSpeedPubTopic>motor_speed/0</motorSpeedPubTopic>
        <rotorVelocitySlowdownSim>10</rotorVelocitySlowdownSim>
        <motorType>velocity</motorType>
      </plugin>
      <plugin name='ignition::gazebo::systems::MulticopterMotorModel' filename='ignition-gazebo-multicopter-motor-model-system'>
        <robotNamespace>X3_2</robotNamespace>
        <jointName>X3_2/rotor_1_joint</jointName>
        <linkName>X3_2/rotor_1</linkName>
        <turningDirection>ccw</turningDirection>
        <timeConstantUp>0.0125</timeConstantUp>
        <timeConstantDown>0.025</timeConstantDown>
        <maxRotVelocity>800.0</maxRotVelocity>
        <motorConstant>8.54858e-06</motorConstant>
        <momentConstant>0.016</momentConstant>
        <commandSubTopic>gazebo/command/motor_speed</commandSubTopic>
        <motorNumber>1</motorNumber>
        <rotorDragCoefficient>8.06428e-05</rotorDragCoefficient>
        <rollingMomentCoefficient>1e-06</rollingMomentCoefficient>
        <motorSpeedPubTopic>motor_speed/1</motorSpeedPubTopic>
        <rotorVelocitySlowdownSim>10</rotorVelocitySlowdownSim>
        <motorType>velocity</motorType>
      </plugin>
      <plugin name='ignition::gazebo::systems::MulticopterMotorModel' filename='ignition-gazebo-multicopter-motor-model-system'>
        <robotNamespace>X3_2</robotNamespace>
        <jointName>X3_2/rotor_2_joint</jointName>
        <linkName>X3_2/rotor_2</linkName>
        <turningDirection>cw</turningDirection>
        <timeConstantUp>0.0125</timeConstantUp>
        <timeConstantDown>0.025</timeConstantDown>
        <maxRotVelocity>800.0</maxRotVelocity>
        <motorConstant>8.54858e-06</motorConstant>
        <momentConstant>0.016</momentConstant>
        <commandSubTopic>gazebo/command/motor_speed</commandSubTopic>
        <motorNumber>2</motorNumber>
        <rotorDragCoefficient>8.06428e-05</rotorDragCoefficient>
        <rollingMomentCoefficient>1e-06</rollingMomentCoefficient>
        <motorSpeedPubTopic>motor_speed/2</motorSpeedPubTopic>
        <rotorVelocitySlowdownSim>10</rotorVelocitySlowdownSim>
        <motorType>velocity</motorType>
      </plugin>
      <plugin name='ignition::gazebo::systems::MulticopterMotorModel' filename='ignition-gazebo-multicopter-motor-model-system'>
        <robotNamespace>X3_2</robotNamespace>
        <jointName>X3_2/rotor_3_joint</jointName>
        <linkName>X3_2/rotor_3</linkName>
        <turningDirection>cw</turningDirection>
        <timeConstantUp>0.0125</timeConstantUp>
        <timeConstantDown>0.025</timeConstantDown>
        <maxRotVelocity>800.0</maxRotVelocity>
        <motorConstant>8.54858e-06</motorConstant>
        <momentConstant>0.016</momentConstant>
        <commandSubTopic>gazebo/command/motor_speed</commandSubTopic>
        <motorNumber>3</motorNumber>
        <rotorDragCoefficient>8.06428e-05</rotorDragCoefficient>
        <rollingMomentCoefficient>1e-06</rollingMomentCoefficient>
        <motorSpeedPubTopic>motor_speed/3</motorSpeedPubTopic>
        <rotorVelocitySlowdownSim>10</rotorVelocitySlowdownSim>
        <motorType>velocity</motorType>
      </plugin>
      <plugin name='ignition::gazebo::systems::MulticopterVelocityControl' filename='ignition-gazebo-multicopter-control-system'>
        <robotNamespace>X3_2</robotNamespace>
        <enableSubTopic>enable</enableSubTopic>
        <comLinkName>X3_2/base_link</comLinkName>
        <velocityGain>2.7 2.7 2.7</velocityGain>
        <attitudeGain>2 3 0.15</attitudeGain>
        <angularRateGain>0.4 0.52 0.18</angularRateGain>
        <maximumLinearAcceleration>2 2 2</maximumLinearAcceleration>
        <maximumLinearVelocity>1 1 1</maximumLinearVelocity>
        <rotorConfiguration>
          <rotor>
            <jointName>X3_2/rotor_0_joint</jointName>
            <forceConstant>8.54858e-06</forceConstant>
            <momentConstant>0.016</momentConstant>
            <direction>1</direction>
          </rotor>
          <rotor>
            <jointName>X3_2/rotor_1_joint</jointName>
            <forceConstant>8.54858e-06</forceConstant>
            <momentConstant>0.016</momentConstant>
            <direction>1</direction>
          </rotor>
          <rotor>
            <jointName>X3_2/rotor_2_joint</jointName>
            <forceConstant>8.54858e-06</forceConstant>
            <momentConstant>0.016</momentConstant>
            <direction>-1</direction>
          </rotor>
          <rotor>
            <jointName>X3_2/rotor_3_joint</jointName>
            <forceConstant>8.54858e-06</forceConstant>
            <momentConstant>0.016</momentConstant>
            <direction>-1</direction>
          </rotor>
        </rotorConfiguration>
      </plugin>
      <plugin name='ignition::gazebo::systems::OdometryPublisher' filename='ignition-gazebo-odometry-publisher-system'>
        <odom_topic>/X3_2/odometry</odom_topic>
        <dimensions>3</dimensions>
      </plugin>
      <static>false</static>
      <self_collide>false</self_collide>
    </model>
    
    <light name='sun' type='directional'>
      <pose>0 0 10 0 -0 0</pose>
      <cast_shadows>true</cast_shadows>
      <intensity>1</intensity>
      <direction>-0.5 0.1 -0.9</direction>
      <diffuse>0.8 0.8 0.8 1</diffuse>
      <specular>0.2 0.2 0.2 1</specular>
      <attenuation>
        <range>1000</range>
        <linear>0.01</linear>
        <constant>0.90000000000000002</constant>
        <quadratic>0.001</quadratic>
      </attenuation>
      <spot>
        <inner_angle>0</inner_angle>
        <outer_angle>0</outer_angle>
        <falloff>0</falloff>
      </spot>
    </light>
  </world>
</sdf>
